Workbook

Sheet Instrucciones
B2: Initiative Accountability Tracker™ — Instrucciones de uso
B4: ESTRUCTURA DEL TRACKER
B5: Este workbook tiene 4 hojas operativas. Cada una cumple un rol específico en el sistema de accountability:
B7: Hoja 1 · Dashboard
B8: Vista consolidada del portfolio. Se actualiza automáticamente cuando se ingresan o modifican datos en la hoja Iniciativas. Incluye conteos por estado, índice de salud del portfolio, y vista de iniciativas en riesgo o retrasadas.
B10: Hoja 2 · Iniciativas
B11: El registro central. Cada fila es una iniciativa estratégica activa. Completar todos los campos: nombre, responsable (una sola persona — no un equipo), categoría, estado, progreso en %, fecha límite, métrica objetivo y última nota de actualización.
B12: Usar el desplegable en la columna Estado para seleccionar: En marcha / En riesgo / Retrasada / Completada / En pausa. No escribir a mano — el Dashboard depende de estos valores exactos.
B14: Hoja 3 · Historial
B15: Registro cronológico de cada actualización. Cada vez que cambia el estado o el progreso de una iniciativa, agregar una fila aquí con: fecha, nombre de la iniciativa, estado anterior, nuevo estado, nota de actualización y próximo paso.
B16: Este historial es la evidencia del accountability. Sin él, el tracker es solo un snapshot. Con él, es un registro de la evolución de cada decisión estratégica.
B18: Hoja 4 · Reporte Ejecutivo
... B37: CRETTA Strategic Leadership Firm · cretta-slf.com

Sheet Dashboard
B2: CRETTA · Initiative Accountability Tracker™ | E2: Dashboard Ejecutivo
B5: TOTAL INICIATIVAS | C5: EN MARCHA | D5: EN RIESGO | E5: RETRASADAS | F5: COMPLETADAS | G5: EN PAUSA
B6: =COUNTA(Iniciativas!B5:B104) -> 5 | C6: =COUNTIF(Iniciativas!E5:E104,"En marcha") -> 2 | D6: =COUNTIF(Iniciativas!E5:E104,"En riesgo") -> 1 | E6: =COUNTIF(Iniciativas!E5:E104,"Retrasada") -> 1 | F6: =COUNTIF(Iniciativas!E5:E104,"Completada") -> 0 | G6: =COUNTIF(Iniciativas!E5:E104,"En pausa") -> 1
B13: ÍNDICE DE SALUD DEL PORTFOLIO
B15: Iniciativas en marcha / Iniciativas activas | C15: =IF((COUNTIF(Iniciativas!E5:E104,"En marcha")+COUNTIF(Iniciativas!E5:E104,"En riesgo")+COUNTIF(Iniciativas!E5:E104,"Retrasada")+COUNTIF(Iniciativas!E5:E104,"En pausa"))=0,0,COUNTIF(Iniciativas!E5:E104,"En marcha")/(COUNTIF(Iniciativas!E5:E104,"En marcha")+COUNTIF(Iniciativas!E5:E104,"En riesgo")+COUNTIF(Iniciativas!E5:E104,"Retrasada")+COUNTIF(Iniciativas!E5:E104,"En pausa"))) -> 0.4 | D15: =IF(C15>=0.75,"Portfolio saludable",IF(C15>=0.5,"Portfolio bajo monitoreo","Portfolio en riesgo — atención requerida")) -> Portfolio en riesgo — atención requerida
B19: ATENCIÓN REQUERIDA — INICIATIVAS EN RIESGO O RETRASADAS
B20: Iniciativa | C20: Responsable | D20: Estado | E20: Progreso | F20: Fecha Límite | G20: Última nota
B21: =IFERROR(INDEX(Iniciativas!B$5:B$104,aggregate(15,6,(ROW(Iniciativas!B$5:B$104)-ROW(Iniciativas!B$5)+1)*((Iniciativas!E$5:E$104="En riesgo")+(Iniciativas!E$5:E$104="Retrasada")),1)),"—") -> — | C21: =IFERROR(INDEX(Iniciativas!C$5:C$104,aggregate(15,6,(ROW(Iniciativas!C$5:C$104)-ROW(Iniciativas!C$5)+1)*((Iniciativas!E$5:E$104="En riesgo")+(Iniciativas!E$5:E$104="Retrasada")),1)),"—") -> — | D21: =IFERROR(INDEX(Iniciativas!E$5:E$104,aggregate(15,6,(ROW(Iniciativas!E$5:E$104)-ROW(Iniciativas!E$5)+1)*((Iniciativas!E$5:E$104="En riesgo")+(Iniciativas!E$5:E$104="Retrasada")),1)),"—") -> — | E21: =IFERROR(INDEX(Iniciativas!F$5:F$104,aggregate(15,6,(ROW(Iniciativas!F$5:F$104)-ROW(Iniciativas!F$5)+1)*((Iniciativas!E$5:E$104="En riesgo")+(Iniciativas!E$5:E$104="Retrasada")),1))/100,"—") -> — | F21: =IFERROR(INDEX(Iniciativas!G$5:G$104,aggregate(15,6,(ROW(Iniciativas!G$5:G$104)-ROW(Iniciativas!G$5)+1)*((Iniciativas!E$5:E$104="En riesgo")+(Iniciativas!E$5:E$104="Retrasada")),1)),"—") -> — | G21: =IFERROR(INDEX(Iniciativas!J$5:J$104,aggregate(15,6,(ROW(Iniciativas!J$5:J$104)-ROW(Iniciativas!J$5)+1)*((Iniciativas!E$5:E$104="En riesgo")+(Iniciativas!E$5:E$104="Retrasada")),1)),"—") -> —
B22: =IFERROR(INDEX(Iniciativas!B$5:B$104,aggregate(15,6,(ROW(Iniciativas!B$5:B$104)-ROW(Iniciativas!B$5)+1)*((Iniciativas!E$5:E$104="En riesgo")+(Iniciativas!E$5:E$104="Retrasada")),2)),"—") -> — | C22: =IFERROR(INDEX(Iniciativas!C$5:C$104,aggregate(15,6,(ROW(Iniciativas!C$5:C$104)-ROW(Iniciativas!C$5)+1)*((Iniciativas!E$5:E$104="En riesgo")+(Iniciativas!E$5:E$104="Retrasada")),2)),"—") -> — | D22: =IFERROR(INDEX(Iniciativas!E$5:E$104,aggregate(15,6,(ROW(Iniciativas!E$5:E$104)-ROW(Iniciativas!E$5)+1)*((Iniciativas!E$5:E$104="En riesgo")+(Iniciativas!E$5:E$104="Retrasada")),2)),"—") -> — | E22: =IFERROR(INDEX(Iniciativas!F$5:F$104,aggregate(15,6,(ROW(Iniciativas!F$5:F$104)-ROW(Iniciativas!F$5)+1)*((Iniciativas!E$5:E$104="En riesgo")+(Iniciativas!E$5:E$104="Retrasada")),2))/100,"—") -> — | F22: =IFERROR(INDEX(Iniciativas!G$5:G$104,aggregate(15,6,(ROW(Iniciativas!G$5:G$104)-ROW(Iniciativas!G$5)+1)*((Iniciativas!E$5:E$104="En riesgo")+(Iniciativas!E$5:E$104="Retrasada")),2)),"—") -> — | G22: =IFERROR(INDEX(Iniciativas!J$5:J$104,aggregate(15,6,(ROW(Iniciativas!J$5:J$104)-ROW(Iniciativas!J$5)+1)*((Iniciativas!E$5:E$104="En riesgo")+(Iniciativas!E$5:E$104="Retrasada")),2)),"—") -> —
B23: =IFERROR(INDEX(Iniciativas!B$5:B$104,aggregate(15,6,(ROW(Iniciativas!B$5:B$104)-ROW(Iniciativas!B$5)+1)*((Iniciativas!E$5:E$104="En riesgo")+(Iniciativas!E$5:E$104="Retrasada")),3)),"—") -> — | C23: =IFERROR(INDEX(Iniciativas!C$5:C$104,aggregate(15,6,(ROW(Iniciativas!C$5:C$104)-ROW(Iniciativas!C$5)+1)*((Iniciativas!E$5:E$104="En riesgo")+(Iniciativas!E$5:E$104="Retrasada")),3)),"—") -> — | D23: =IFERROR(INDEX(Iniciativas!E$5:E$104,aggregate(15,6,(ROW(Iniciativas!E$5:E$104)-ROW(Iniciativas!E$5)+1)*((Iniciativas!E$5:E$104="En riesgo")+(Iniciativas!E$5:E$104="Retrasada")),3)),"—") -> — | E23: =IFERROR(INDEX(Iniciativas!F$5:F$104,aggregate(15,6,(ROW(Iniciativas!F$5:F$104)-ROW(Iniciativas!F$5)+1)*((Iniciativas!E$5:E$104="En riesgo")+(Iniciativas!E$5:E$104="Retrasada")),3))/100,"—") -> — | F23: =IFERROR(INDEX(Iniciativas!G$5:G$104,aggregate(15,6,(ROW(Iniciativas!G$5:G$104)-ROW(Iniciativas!G$5)+1)*((Iniciativas!E$5:E$104="En riesgo")+(Iniciativas!E$5:E$104="Retrasada")),3)),"—") -> — | G23: =IFERROR(INDEX(Iniciativas!J$5:J$104,aggregate(15,6,(ROW(Iniciativas!J$5:J$104)-ROW(Iniciativas!J$5)+1)*((Iniciativas!E$5:E$104="En riesgo")+(Iniciativas!E$5:E$104="Retrasada")),3)),"—") -> —
B24: =IFERROR(INDEX(Iniciativas!B$5:B$104,aggregate(15,6,(ROW(Iniciativas!B$5:B$104)-ROW(Iniciativas!B$5)+1)*((Iniciativas!E$5:E$104="En riesgo")+(Iniciativas!E$5:E$104="Retrasada")),4)),"—") -> — | C24: =IFERROR(INDEX(Iniciativas!C$5:C$104,aggregate(15,6,(ROW(Iniciativas!C$5:C$104)-ROW(Iniciativas!C$5)+1)*((Iniciativas!E$5:E$104="En riesgo")+(Iniciativas!E$5:E$104="Retrasada")),4)),"—") -> — | D24: =IFERROR(INDEX(Iniciativas!E$5:E$104,aggregate(15,6,(ROW(Iniciativas!E$5:E$104)-ROW(Iniciativas!E$5)+1)*((Iniciativas!E$5:E$104="En riesgo")+(Iniciativas!E$5:E$104="Retrasada")),4)),"—") -> — | E24: =IFERROR(INDEX(Iniciativas!F$5:F$104,aggregate(15,6,(ROW(Iniciativas!F$5:F$104)-ROW(Iniciativas!F$5)+1)*((Iniciativas!E$5:E$104="En riesgo")+(Iniciativas!E$5:E$104="Retrasada")),4))/100,"—") -> — | F24: =IFERROR(INDEX(Iniciativas!G$5:G$104,aggregate(15,6,(ROW(Iniciativas!G$5:G$104)-ROW(Iniciativas!G$5)+1)*((Iniciativas!E$5:E$104="En riesgo")+(Iniciativas!E$5:E$104="Retrasada")),4)),"—") -> — | G24: =IFERROR(INDEX(Iniciativas!J$5:J$104,aggregate(15,6,(ROW(Iniciativas!J$5:J$104)-ROW(Iniciativas!J$5)+1)*((Iniciativas!E$5:E$104="En riesgo")+(Iniciativas!E$5:E$104="Retrasada")),4)),"—") -> —
B25: =IFERROR(INDEX(Iniciativas!B$5:B$104,aggregate(15,6,(ROW(Iniciativas!B$5:B$104)-ROW(Iniciativas!B$5)+1)*((Iniciativas!E$5:E$104="En riesgo")+(Iniciativas!E$5:E$104="Retrasada")),5)),"—") -> — | C25: =IFERROR(INDEX(Iniciativas!C$5:C$104,aggregate(15,6,(ROW(Iniciativas!C$5:C$104)-ROW(Iniciativas!C$5)+1)*((Iniciativas!E$5:E$104="En riesgo")+(Iniciativas!E$5:E$104="Retrasada")),5)),"—") -> — | D25: =IFERROR(INDEX(Iniciativas!E$5:E$104,aggregate(15,6,(ROW(Iniciativas!E$5:E$104)-ROW(Iniciativas!E$5)+1)*((Iniciativas!E$5:E$104="En riesgo")+(Iniciativas!E$5:E$104="Retrasada")),5)),"—") -> — | E25: =IFERROR(INDEX(Iniciativas!F$5:F$104,aggregate(15,6,(ROW(Iniciativas!F$5:F$104)-ROW(Iniciativas!F$5)+1)*((Iniciativas!E$5:E$104="En riesgo")+(Iniciativas!E$5:E$104="Retrasada")),5))/100,"—") -> — | F25: =IFERROR(INDEX(Iniciativas!G$5:G$104,aggregate(15,6,(ROW(Iniciativas!G$5:G$104)-ROW(Iniciativas!G$5)+1)*((Iniciativas!E$5:E$104="En riesgo")+(Iniciativas!E$5:E$104="Retrasada")),5)),"—") -> — | G25: =IFERROR(INDEX(Iniciativas!J$5:J$104,aggregate(15,6,(ROW(Iniciativas!J$5:J$104)-ROW(Iniciativas!J$5)+1)*((Iniciativas!E$5:E$104="En riesgo")+(Iniciativas!E$5:E$104="Retrasada")),5)),"—") -> —
B26: =IFERROR(INDEX(Iniciativas!B$5:B$104,aggregate(15,6,(ROW(Iniciativas!B$5:B$104)-ROW(Iniciativas!B$5)+1)*((Iniciativas!E$5:E$104="En riesgo")+(Iniciativas!E$5:E$104="Retrasada")),6)),"—") -> — | C26: =IFERROR(INDEX(Iniciativas!C$5:C$104,aggregate(15,6,(ROW(Iniciativas!C$5:C$104)-ROW(Iniciativas!C$5)+1)*((Iniciativas!E$5:E$104="En riesgo")+(Iniciativas!E$5:E$104="Retrasada")),6)),"—") -> — | D26: =IFERROR(INDEX(Iniciativas!E$5:E$104,aggregate(15,6,(ROW(Iniciativas!E$5:E$104)-ROW(Iniciativas!E$5)+1)*((Iniciativas!E$5:E$104="En riesgo")+(Iniciativas!E$5:E$104="Retrasada")),6)),"—") -> — | E26: =IFERROR(INDEX(Iniciativas!F$5:F$104,aggregate(15,6,(ROW(Iniciativas!F$5:F$104)-ROW(Iniciativas!F$5)+1)*((Iniciativas!E$5:E$104="En riesgo")+(Iniciativas!E$5:E$104="Retrasada")),6))/100,"—") -> — | F26: =IFERROR(INDEX(Iniciativas!G$5:G$104,aggregate(15,6,(ROW(Iniciativas!G$5:G$104)-ROW(Iniciativas!G$5)+1)*((Iniciativas!E$5:E$104="En riesgo")+(Iniciativas!E$5:E$104="Retrasada")),6)),"—") -> — | G26: =IFERROR(INDEX(Iniciativas!J$5:J$104,aggregate(15,6,(ROW(Iniciativas!J$5:J$104)-ROW(Iniciativas!J$5)+1)*((Iniciativas!E$5:E$104="En riesgo")+(Iniciativas!E$5:E$104="Retrasada")),6)),"—") -> —
B27: =IFERROR(INDEX(Iniciativas!B$5:B$104,aggregate(15,6,(ROW(Iniciativas!B$5:B$104)-ROW(Iniciativas!B$5)+1)*((Iniciativas!E$5:E$104="En riesgo")+(Iniciativas!E$5:E$104="Retrasada")),7)),"—") -> — | C27: =IFERROR(INDEX(Iniciativas!C$5:C$104,aggregate(15,6,(ROW(Iniciativas!C$5:C$104)-ROW(Iniciativas!C$5)+1)*((Iniciativas!E$5:E$104="En riesgo")+(Iniciativas!E$5:E$104="Retrasada")),7)),"—") -> — | D27: =IFERROR(INDEX(Iniciativas!E$5:E$104,aggregate(15,6,(ROW(Iniciativas!E$5:E$104)-ROW(Iniciativas!E$5)+1)*((Iniciativas!E$5:E$104="En riesgo")+(Iniciativas!E$5:E$104="Retrasada")),7)),"—") -> — | E27: =IFERROR(INDEX(Iniciativas!F$5:F$104,aggregate(15,6,(ROW(Iniciativas!F$5:F$104)-ROW(Iniciativas!F$5)+1)*((Iniciativas!E$5:E$104="En riesgo")+(Iniciativas!E$5:E$104="Retrasada")),7))/100,"—") -> — | F27: =IFERROR(INDEX(Iniciativas!G$5:G$104,aggregate(15,6,(ROW(Iniciativas!G$5:G$104)-ROW(Iniciativas!G$5)+1)*((Iniciativas!E$5:E$104="En riesgo")+(Iniciativas!E$5:E$104="Retrasada")),7)),"—") -> — | G27: =IFERROR(INDEX(Iniciativas!J$5:J$104,aggregate(15,6,(ROW(Iniciativas!J$5:J$104)-ROW(Iniciativas!J$5)+1)*((Iniciativas!E$5:E$104="En riesgo")+(Iniciativas!E$5:E$104="Retrasada")),7)),"—") -> —
B29: DISTRIBUCIÓN POR CATEGORÍA | F29: PROGRESO PROMEDIO POR ESTADO
B30: Estrategia | C30: =COUNTIF(Iniciativas!D$5:D$104,"Estrategia") -> 0 | D30: =IFERROR(AVERAGEIF(Iniciativas!D$5:D$104,"Estrategia",Iniciativas!F$5:F$104)/100,"-") -> - | F30: En marcha | G30: =IFERROR(AVERAGEIF(Iniciativas!E$5:E$104,"En marcha",Iniciativas!F$5:F$104)/100,"-") -> 0.00475
B31: Crecimiento | C31: =COUNTIF(Iniciativas!D$5:D$104,"Crecimiento") -> 1 | D31: =IFERROR(AVERAGEIF(Iniciativas!D$5:D$104,"Crecimiento",Iniciativas!F$5:F$104)/100,"-") -> 0.0035 | F31: En riesgo | G31: =IFERROR(AVERAGEIF(Iniciativas!E$5:E$104,"En riesgo",Iniciativas!F$5:F$104)/100,"-") -> 0.002
B32: Operaciones | C32: =COUNTIF(Iniciativas!D$5:D$104,"Operaciones") -> 1 | D32: =IFERROR(AVERAGEIF(Iniciativas!D$5:D$104,"Operaciones",Iniciativas!F$5:F$104)/100,"-") -> 0.006 | F32: Retrasada | G32: =IFERROR(AVERAGEIF(Iniciativas!E$5:E$104,"Retrasada",Iniciativas!F$5:F$104)/100,"-") -> 0.0015
B33: Talento | C33: =COUNTIF(Iniciativas!D$5:D$104,"Talento") -> 1 | D33: =IFERROR(AVERAGEIF(Iniciativas!D$5:D$104,"Talento",Iniciativas!F$5:F$104)/100,"-") -> 0.001 | F33: Completada | G33: =IFERROR(AVERAGEIF(Iniciativas!E$5:E$104,"Completada",Iniciativas!F$5:F$104)/100,"-") -> -
B34: Gobierno | C34: =COUNTIF(Iniciativas!D$5:D$104,"Gobierno") -> 2 | D34: =IFERROR(AVERAGEIF(Iniciativas!D$5:D$104,"Gobierno",Iniciativas!F$5:F$104)/100,"-") -> 0.00175 | F34: En pausa | G34: =IFERROR(AVERAGEIF(Iniciativas!E$5:E$104,"En pausa",Iniciativas!F$5:F$104)/100,"-") -> 0.001
B35: Capital | C35: =COUNTIF(Iniciativas!D$5:D$104,"Capital") -> 0 | D35: =IFERROR(AVERAGEIF(Iniciativas!D$5:D$104,"Capital",Iniciativas!F$5:F$104)/100,"-") -> -
B36: Transformación | C36: =COUNTIF(Iniciativas!D$5:D$104,"Transformación") -> 0 | D36: =IFERROR(AVERAGEIF(Iniciativas!D$5:D$104,"Transformación",Iniciativas!F$5:F$104)/100,"-") -> -
B37: Mercado | C37: =COUNTIF(Iniciativas!D$5:D$104,"Mercado") -> 0 | D37: =IFERROR(AVERAGEIF(Iniciativas!D$5:D$104,"Mercado",Iniciativas!F$5:F$104)/100,"-") -> -
B45: CRETTA Strategic Leadership Firm · Initiative Accountability Tracker™ · Uso exclusivo del equipo directivo

Sheet Iniciativas
B2: CRETTA · Initiative Accountability Tracker™ | E2: Registro de Iniciativas Estratégicas
B4: INICIATIVA ESTRATÉGICA | C4: RESPONSABLE (OWNER) | D4: CATEGORÍA | E4: ESTADO | F4: PROGRESO (%) | G4: FECHA LÍMITE | H4: FECHA INICIO | I4: MÉTRICA OBJETIVO | J4: ÚLTIMA ACTUALIZACIÓN / NOTA | K4: PRÓXIMO PASO | L4: DÍAS RESTANTES
B5: Expansión a Monterrey — apertura de operaciones EPC | C5: Luis Fernández | D5: Crecimiento | E5: En marcha | F5: 0.35 | G5: 2026-09-30 | H5: 2026-01-15 | I5: Primer contrato firmado en Q3 2026 | J5: Reunión con cliente ancla el 12 de mayo. Proceso de licitación en curso. | K5: Confirmar equipo de obra local antes del 15 de mayo | L5: =IFERROR(IF(G5="","—",IF(E5="Completada","✓",G5-TODAY())),"—") -> 151
B6: Estructuración del Consejo de Administración | C6: CEO | D6: Gobierno | E6: En riesgo | F6: 0.2 | G6: 2026-06-30 | H6: 2026-02-01 | I6: Consejo operativo con 1 consejero independiente | J6: El proceso de selección del consejero independiente está retrasado 3 semanas. | K6: Reactivar búsqueda — contactar a 3 candidatos esta semana | L6: =IFERROR(IF(G6="","—",IF(E6="Completada","✓",G6-TODAY())),"—") -> 59
B7: Implementación del sistema ERP | C7: Claudia Ramírez | D7: Operaciones | E7: En marcha | F7: 0.6 | G7: 2026-07-31 | H7: 2025-11-01 | I7: Go-live del módulo financiero | J7: Módulo de compras completado. Módulo financiero en fase de pruebas. | K7: Cierre de UAT fase 2 el 28 de mayo | L7: =IFERROR(IF(G7="","—",IF(E7="Completada","✓",G7-TODAY())),"—") -> 90
B8: Plan de sucesión del CEO | C8: Consejo | D8: Talento | E8: En pausa | F8: 0.1 | G8: 2026-12-31 | H8: 2026-03-01 | I8: Sucesor identificado y plan documentado | J8: En espera de definición del horizonte de transición por parte de los socios. | K8: Sesión de alineación de socios en junio | L8: =IFERROR(IF(G8="","—",IF(E8="Completada","✓",G8-TODAY())),"—") -> 243
B9: Protocolo familiar — primera versión | C9: Asesor Legal | D9: Gobierno | E9: Retrasada | F9: 0.15 | G9: 2026-05-31 | H9: 2026-01-10 | I9: Documento aprobado por todos los socios | J9: Conflicto entre socios sobre cláusula de liquidez bloqueó el proceso. | K9: Mediación con facilitador externo — fecha por confirmar | L9: =IFERROR(IF(G9="","—",IF(E9="Completada","✓",G9-TODAY())),"—") -> 29
L10: =IFERROR(IF(G10="","—",IF(E10="Completada","✓",G10-TODAY())),"—") -> —
L11: =IFERROR(IF(G11="","—",IF(E11="Completada","✓",G11-TODAY())),"—") -> —
L12: =IFERROR(IF(G12="","—",IF(E12="Completada","✓",G12-TODAY())),"—") -> —
L13: =IFERROR(IF(G13="","—",IF(E13="Completada","✓",G13-TODAY())),"—") -> —
L14: =IFERROR(IF(G14="","—",IF(E14="Completada","✓",G14-TODAY())),"—") -> —
L15: =IFERROR(IF(G15="","—",IF(E15="Completada","✓",G15-TODAY())),"—") -> —
L16: =IFERROR(IF(G16="","—",IF(E16="Completada","✓",G16-TODAY())),"—") -> —
L17: =IFERROR(IF(G17="","—",IF(E17="Completada","✓",G17-TODAY())),"—") -> —
L18: =IFERROR(IF(G18="","—",IF(E18="Completada","✓",G18-TODAY())),"—") -> —
L19: =IFERROR(IF(G19="","—",IF(E19="Completada","✓",G19-TODAY())),"—") -> —
L20: =IFERROR(IF(G20="","—",IF(E20="Completada","✓",G20-TODAY())),"—") -> —
L21: =IFERROR(IF(G21="","—",IF(E21="Completada","✓",G21-TODAY())),"—") -> —
... L104: =IFERROR(IF(G104="","—",IF(E104="Completada","✓",G104-TODAY())),"—") -> —

Sheet Historial
B2: CRETTA · Initiative Accountability Tracker™ | E2: Historial de Actualizaciones
B4: FECHA | C4: INICIATIVA ESTRATÉGICA | D4: RESPONSABLE | E4: ESTADO ANTERIOR | F4: NUEVO ESTADO | G4: NOTA DE ACTUALIZACIÓN | H4: PRÓXIMO PASO / COMPROMISO | I4: REGISTRADO POR
B5: 2026-04-28 | C5: Expansión a Monterrey — apertura de operaciones EPC | D5: Luis Fernández | E5: En riesgo | F5: En marcha | G5: Se firmó carta de intención con cliente ancla. Riesgo de financiamiento resuelto. | H5: Presentar propuesta técnica definitiva el 15 de mayo | I5: CEO
B6: 2026-04-21 | C6: Estructuración del Consejo de Administración | D6: CEO | E6: En marcha | F6: En riesgo | G6: El candidato principal declinó. Proceso de búsqueda debe reiniciarse. | H6: Contactar a 3 candidatos alternativos esta semana | I6: CEO
B7: 2026-04-14 | C7: Implementación del sistema ERP | D7: Claudia Ramírez | E7: En marcha | F7: En marcha | G7: Módulo de compras completado al 100%. Módulo financiero inicia pruebas. | H7: Cerrar UAT fase 2 el 28 de mayo con equipo de finanzas | I7: Claudia Ramírez
B8: 2026-03-31 | C8: Protocolo familiar — primera versión | D8: Asesor Legal | E8: En marcha | F8: Retrasada | G8: Desacuerdo entre socios sobre la cláusula de liquidez. Proceso detenido. | H8: Convocar sesión de mediación con facilitador externo | I8: CEO
B306: Registrar cada actualización en este historial — la cadencia de registro es la evidencia del accountability

Sheet Reporte Ejecutivo
B2: REPORTE EJECUTIVO DE INICIATIVAS | F2: =TODAY() -> 46144
B4: RESUMEN DEL PERÍODO
B5: Total iniciativas en seguimiento | C5: =COUNTA(Iniciativas!B5:B104) -> 5
B6: Iniciativas en marcha | C6: =COUNTIF(Iniciativas!E5:E104,"En marcha") -> 2
B7: Iniciativas en riesgo | C7: =COUNTIF(Iniciativas!E5:E104,"En riesgo") -> 1
B8: Iniciativas retrasadas | C8: =COUNTIF(Iniciativas!E5:E104,"Retrasada") -> 1
B9: Iniciativas completadas | C9: =COUNTIF(Iniciativas!E5:E104,"Completada") -> 0
B10: Progreso promedio del portfolio | C10: =IFERROR(AVERAGEIF(Iniciativas!E5:E104,"<>Completada",Iniciativas!F5:F104)/100,0) -> 0.0028
B11: Índice de salud del portfolio | C11: =IFERROR(COUNTIF(Iniciativas!E5:E104,"En marcha")/(COUNTIF(Iniciativas!E5:E104,"En marcha")+COUNTIF(Iniciativas!E5:E104,"En riesgo")+COUNTIF(Iniciativas!E5:E104,"Retrasada")+COUNTIF(Iniciativas!E5:E104,"En pausa")),0) -> 0.4
B13: ESTADO DETALLADO DE INICIATIVAS ACTIVAS
B14: INICIATIVA | C14: RESPONSABLE | D14: ESTADO | E14: PROGRESO | F14: FECHA LÍMITE | G14: ÚLTIMA ACTUALIZACIÓN
B15: =IFERROR(INDEX(Iniciativas!B$5:B$104,aggregate(15,6,(ROW(Iniciativas!B$5:B$104)-ROW(Iniciativas!B$5)+1)*(Iniciativas!E$5:E$104<>"Completada"),1)),"—") -> — | C15: =IFERROR(INDEX(Iniciativas!C$5:C$104,aggregate(15,6,(ROW(Iniciativas!B$5:B$104)-ROW(Iniciativas!B$5)+1)*(Iniciativas!E$5:E$104<>"Completada"),1)),"—") -> — | D15: =IFERROR(INDEX(Iniciativas!E$5:E$104,aggregate(15,6,(ROW(Iniciativas!B$5:B$104)-ROW(Iniciativas!B$5)+1)*(Iniciativas!E$5:E$104<>"Completada"),1)),"—") -> — | E15: =IFERROR(INDEX(Iniciativas!F$5:F$104,aggregate(15,6,(ROW(Iniciativas!B$5:B$104)-ROW(Iniciativas!B$5)+1)*(Iniciativas!E$5:E$104<>"Completada"),1))/100,"—") -> — | F15: =IFERROR(INDEX(Iniciativas!G$5:G$104,aggregate(15,6,(ROW(Iniciativas!B$5:B$104)-ROW(Iniciativas!B$5)+1)*(Iniciativas!E$5:E$104<>"Completada"),1)),"—") -> — | G15: =IFERROR(INDEX(Iniciativas!J$5:J$104,aggregate(15,6,(ROW(Iniciativas!B$5:B$104)-ROW(Iniciativas!B$5)+1)*(Iniciativas!E$5:E$104<>"Completada"),1)),"—") -> —
B16: =IFERROR(INDEX(Iniciativas!B$5:B$104,aggregate(15,6,(ROW(Iniciativas!B$5:B$104)-ROW(Iniciativas!B$5)+1)*(Iniciativas!E$5:E$104<>"Completada"),2)),"—") -> — | C16: =IFERROR(INDEX(Iniciativas!C$5:C$104,aggregate(15,6,(ROW(Iniciativas!B$5:B$104)-ROW(Iniciativas!B$5)+1)*(Iniciativas!E$5:E$104<>"Completada"),2)),"—") -> — | D16: =IFERROR(INDEX(Iniciativas!E$5:E$104,aggregate(15,6,(ROW(Iniciativas!B$5:B$104)-ROW(Iniciativas!B$5)+1)*(Iniciativas!E$5:E$104<>"Completada"),2)),"—") -> — | E16: =IFERROR(INDEX(Iniciativas!F$5:F$104,aggregate(15,6,(ROW(Iniciativas!B$5:B$104)-ROW(Iniciativas!B$5)+1)*(Iniciativas!E$5:E$104<>"Completada"),2))/100,"—") -> — | F16: =IFERROR(INDEX(Iniciativas!G$5:G$104,aggregate(15,6,(ROW(Iniciativas!B$5:B$104)-ROW(Iniciativas!B$5)+1)*(Iniciativas!E$5:E$104<>"Completada"),2)),"—") -> — | G16: =IFERROR(INDEX(Iniciativas!J$5:J$104,aggregate(15,6,(ROW(Iniciativas!B$5:B$104)-ROW(Iniciativas!B$5)+1)*(Iniciativas!E$5:E$104<>"Completada"),2)),"—") -> —
B17: =IFERROR(INDEX(Iniciativas!B$5:B$104,aggregate(15,6,(ROW(Iniciativas!B$5:B$104)-ROW(Iniciativas!B$5)+1)*(Iniciativas!E$5:E$104<>"Completada"),3)),"—") -> — | C17: =IFERROR(INDEX(Iniciativas!C$5:C$104,aggregate(15,6,(ROW(Iniciativas!B$5:B$104)-ROW(Iniciativas!B$5)+1)*(Iniciativas!E$5:E$104<>"Completada"),3)),"—") -> — | D17: =IFERROR(INDEX(Iniciativas!E$5:E$104,aggregate(15,6,(ROW(Iniciativas!B$5:B$104)-ROW(Iniciativas!B$5)+1)*(Iniciativas!E$5:E$104<>"Completada"),3)),"—") -> — | E17: =IFERROR(INDEX(Iniciativas!F$5:F$104,aggregate(15,6,(ROW(Iniciativas!B$5:B$104)-ROW(Iniciativas!B$5)+1)*(Iniciativas!E$5:E$104<>"Completada"),3))/100,"—") -> — | F17: =IFERROR(INDEX(Iniciativas!G$5:G$104,aggregate(15,6,(ROW(Iniciativas!B$5:B$104)-ROW(Iniciativas!B$5)+1)*(Iniciativas!E$5:E$104<>"Completada"),3)),"—") -> — | G17: =IFERROR(INDEX(Iniciativas!J$5:J$104,aggregate(15,6,(ROW(Iniciativas!B$5:B$104)-ROW(Iniciativas!B$5)+1)*(Iniciativas!E$5:E$104<>"Completada"),3)),"—") -> —
B18: =IFERROR(INDEX(Iniciativas!B$5:B$104,aggregate(15,6,(ROW(Iniciativas!B$5:B$104)-ROW(Iniciativas!B$5)+1)*(Iniciativas!E$5:E$104<>"Completada"),4)),"—") -> — | C18: =IFERROR(INDEX(Iniciativas!C$5:C$104,aggregate(15,6,(ROW(Iniciativas!B$5:B$104)-ROW(Iniciativas!B$5)+1)*(Iniciativas!E$5:E$104<>"Completada"),4)),"—") -> — | D18: =IFERROR(INDEX(Iniciativas!E$5:E$104,aggregate(15,6,(ROW(Iniciativas!B$5:B$104)-ROW(Iniciativas!B$5)+1)*(Iniciativas!E$5:E$104<>"Completada"),4)),"—") -> — | E18: =IFERROR(INDEX(Iniciativas!F$5:F$104,aggregate(15,6,(ROW(Iniciativas!B$5:B$104)-ROW(Iniciativas!B$5)+1)*(Iniciativas!E$5:E$104<>"Completada"),4))/100,"—") -> — | F18: =IFERROR(INDEX(Iniciativas!G$5:G$104,aggregate(15,6,(ROW(Iniciativas!B$5:B$104)-ROW(Iniciativas!B$5)+1)*(Iniciativas!E$5:E$104<>"Completada"),4)),"—") -> — | G18: =IFERROR(INDEX(Iniciativas!J$5:J$104,aggregate(15,6,(ROW(Iniciativas!B$5:B$104)-ROW(Iniciativas!B$5)+1)*(Iniciativas!E$5:E$104<>"Completada"),4)),"—") -> —
B19: =IFERROR(INDEX(Iniciativas!B$5:B$104,aggregate(15,6,(ROW(Iniciativas!B$5:B$104)-ROW(Iniciativas!B$5)+1)*(Iniciativas!E$5:E$104<>"Completada"),5)),"—") -> — | C19: =IFERROR(INDEX(Iniciativas!C$5:C$104,aggregate(15,6,(ROW(Iniciativas!B$5:B$104)-ROW(Iniciativas!B$5)+1)*(Iniciativas!E$5:E$104<>"Completada"),5)),"—") -> — | D19: =IFERROR(INDEX(Iniciativas!E$5:E$104,aggregate(15,6,(ROW(Iniciativas!B$5:B$104)-ROW(Iniciativas!B$5)+1)*(Iniciativas!E$5:E$104<>"Completada"),5)),"—") -> — | E19: =IFERROR(INDEX(Iniciativas!F$5:F$104,aggregate(15,6,(ROW(Iniciativas!B$5:B$104)-ROW(Iniciativas!B$5)+1)*(Iniciativas!E$5:E$104<>"Completada"),5))/100,"—") -> — | F19: =IFERROR(INDEX(Iniciativas!G$5:G$104,aggregate(15,6,(ROW(Iniciativas!B$5:B$104)-ROW(Iniciativas!B$5)+1)*(Iniciativas!E$5:E$104<>"Completada"),5)),"—") -> — | G19: =IFERROR(INDEX(Iniciativas!J$5:J$104,aggregate(15,6,(ROW(Iniciativas!B$5:B$104)-ROW(Iniciativas!B$5)+1)*(Iniciativas!E$5:E$104<>"Completada"),5)),"—") -> —
B20: =IFERROR(INDEX(Iniciativas!B$5:B$104,aggregate(15,6,(ROW(Iniciativas!B$5:B$104)-ROW(Iniciativas!B$5)+1)*(Iniciativas!E$5:E$104<>"Completada"),6)),"—") -> — | C20: =IFERROR(INDEX(Iniciativas!C$5:C$104,aggregate(15,6,(ROW(Iniciativas!B$5:B$104)-ROW(Iniciativas!B$5)+1)*(Iniciativas!E$5:E$104<>"Completada"),6)),"—") -> — | D20: =IFERROR(INDEX(Iniciativas!E$5:E$104,aggregate(15,6,(ROW(Iniciativas!B$5:B$104)-ROW(Iniciativas!B$5)+1)*(Iniciativas!E$5:E$104<>"Completada"),6)),"—") -> — | E20: =IFERROR(INDEX(Iniciativas!F$5:F$104,aggregate(15,6,(ROW(Iniciativas!B$5:B$104)-ROW(Iniciativas!B$5)+1)*(Iniciativas!E$5:E$104<>"Completada"),6))/100,"—") -> — | F20: =IFERROR(INDEX(Iniciativas!G$5:G$104,aggregate(15,6,(ROW(Iniciativas!B$5:B$104)-ROW(Iniciativas!B$5)+1)*(Iniciativas!E$5:E$104<>"Completada"),6)),"—") -> — | G20: =IFERROR(INDEX(Iniciativas!J$5:J$104,aggregate(15,6,(ROW(Iniciativas!B$5:B$104)-ROW(Iniciativas!B$5)+1)*(Iniciativas!E$5:E$104<>"Completada"),6)),"—") -> —
B21: =IFERROR(INDEX(Iniciativas!B$5:B$104,aggregate(15,6,(ROW(Iniciativas!B$5:B$104)-ROW(Iniciativas!B$5)+1)*(Iniciativas!E$5:E$104<>"Completada"),7)),"—") -> — | C21: =IFERROR(INDEX(Iniciativas!C$5:C$104,aggregate(15,6,(ROW(Iniciativas!B$5:B$104)-ROW(Iniciativas!B$5)+1)*(Iniciativas!E$5:E$104<>"Completada"),7)),"—") -> — | D21: =IFERROR(INDEX(Iniciativas!E$5:E$104,aggregate(15,6,(ROW(Iniciativas!B$5:B$104)-ROW(Iniciativas!B$5)+1)*(Iniciativas!E$5:E$104<>"Completada"),7)),"—") -> — | E21: =IFERROR(INDEX(Iniciativas!F$5:F$104,aggregate(15,6,(ROW(Iniciativas!B$5:B$104)-ROW(Iniciativas!B$5)+1)*(Iniciativas!E$5:E$104<>"Completada"),7))/100,"—") -> — | F21: =IFERROR(INDEX(Iniciativas!G$5:G$104,aggregate(15,6,(ROW(Iniciativas!B$5:B$104)-ROW(Iniciativas!B$5)+1)*(Iniciativas!E$5:E$104<>"Completada"),7)),"—") -> — | G21: =IFERROR(INDEX(Iniciativas!J$5:J$104,aggregate(15,6,(ROW(Iniciativas!B$5:B$104)-ROW(Iniciativas!B$5)+1)*(Iniciativas!E$5:E$104<>"Completada"),7)),"—") -> —
B22: =IFERROR(INDEX(Iniciativas!B$5:B$104,aggregate(15,6,(ROW(Iniciativas!B$5:B$104)-ROW(Iniciativas!B$5)+1)*(Iniciativas!E$5:E$104<>"Completada"),8)),"—") -> — | C22: =IFERROR(INDEX(Iniciativas!C$5:C$104,aggregate(15,6,(ROW(Iniciativas!B$5:B$104)-ROW(Iniciativas!B$5)+1)*(Iniciativas!E$5:E$104<>"Completada"),8)),"—") -> — | D22: =IFERROR(INDEX(Iniciativas!E$5:E$104,aggregate(15,6,(ROW(Iniciativas!B$5:B$104)-ROW(Iniciativas!B$5)+1)*(Iniciativas!E$5:E$104<>"Completada"),8)),"—") -> — | E22: =IFERROR(INDEX(Iniciativas!F$5:F$104,aggregate(15,6,(ROW(Iniciativas!B$5:B$104)-ROW(Iniciativas!B$5)+1)*(Iniciativas!E$5:E$104<>"Completada"),8))/100,"—") -> — | F22: =IFERROR(INDEX(Iniciativas!G$5:G$104,aggregate(15,6,(ROW(Iniciativas!B$5:B$104)-ROW(Iniciativas!B$5)+1)*(Iniciativas!E$5:E$104<>"Completada"),8)),"—") -> — | G22: =IFERROR(INDEX(Iniciativas!J$5:J$104,aggregate(15,6,(ROW(Iniciativas!B$5:B$104)-ROW(Iniciativas!B$5)+1)*(Iniciativas!E$5:E$104<>"Completada"),8)),"—") -> —
B23: =IFERROR(INDEX(Iniciativas!B$5:B$104,aggregate(15,6,(ROW(Iniciativas!B$5:B$104)-ROW(Iniciativas!B$5)+1)*(Iniciativas!E$5:E$104<>"Completada"),9)),"—") -> — | C23: =IFERROR(INDEX(Iniciativas!C$5:C$104,aggregate(15,6,(ROW(Iniciativas!B$5:B$104)-ROW(Iniciativas!B$5)+1)*(Iniciativas!E$5:E$104<>"Completada"),9)),"—") -> — | D23: =IFERROR(INDEX(Iniciativas!E$5:E$104,aggregate(15,6,(ROW(Iniciativas!B$5:B$104)-ROW(Iniciativas!B$5)+1)*(Iniciativas!E$5:E$104<>"Completada"),9)),"—") -> — | E23: =IFERROR(INDEX(Iniciativas!F$5:F$104,aggregate(15,6,(ROW(Iniciativas!B$5:B$104)-ROW(Iniciativas!B$5)+1)*(Iniciativas!E$5:E$104<>"Completada"),9))/100,"—") -> — | F23: =IFERROR(INDEX(Iniciativas!G$5:G$104,aggregate(15,6,(ROW(Iniciativas!B$5:B$104)-ROW(Iniciativas!B$5)+1)*(Iniciativas!E$5:E$104<>"Completada"),9)),"—") -> — | G23: =IFERROR(INDEX(Iniciativas!J$5:J$104,aggregate(15,6,(ROW(Iniciativas!B$5:B$104)-ROW(Iniciativas!B$5)+1)*(Iniciativas!E$5:E$104<>"Completada"),9)),"—") -> —
B24: =IFERROR(INDEX(Iniciativas!B$5:B$104,aggregate(15,6,(ROW(Iniciativas!B$5:B$104)-ROW(Iniciativas!B$5)+1)*(Iniciativas!E$5:E$104<>"Completada"),10)),"—") -> — | C24: =IFERROR(INDEX(Iniciativas!C$5:C$104,aggregate(15,6,(ROW(Iniciativas!B$5:B$104)-ROW(Iniciativas!B$5)+1)*(Iniciativas!E$5:E$104<>"Completada"),10)),"—") -> — | D24: =IFERROR(INDEX(Iniciativas!E$5:E$104,aggregate(15,6,(ROW(Iniciativas!B$5:B$104)-ROW(Iniciativas!B$5)+1)*(Iniciativas!E$5:E$104<>"Completada"),10)),"—") -> — | E24: =IFERROR(INDEX(Iniciativas!F$5:F$104,aggregate(15,6,(ROW(Iniciativas!B$5:B$104)-ROW(Iniciativas!B$5)+1)*(Iniciativas!E$5:E$104<>"Completada"),10))/100,"—") -> — | F24: =IFERROR(INDEX(Iniciativas!G$5:G$104,aggregate(15,6,(ROW(Iniciativas!B$5:B$104)-ROW(Iniciativas!B$5)+1)*(Iniciativas!E$5:E$104<>"Completada"),10)),"—") -> — | G24: =IFERROR(INDEX(Iniciativas!J$5:J$104,aggregate(15,6,(ROW(Iniciativas!B$5:B$104)-ROW(Iniciativas!B$5)+1)*(Iniciativas!E$5:E$104<>"Completada"),10)),"—") -> —
B25: =IFERROR(INDEX(Iniciativas!B$5:B$104,aggregate(15,6,(ROW(Iniciativas!B$5:B$104)-ROW(Iniciativas!B$5)+1)*(Iniciativas!E$5:E$104<>"Completada"),11)),"—") -> — | C25: =IFERROR(INDEX(Iniciativas!C$5:C$104,aggregate(15,6,(ROW(Iniciativas!B$5:B$104)-ROW(Iniciativas!B$5)+1)*(Iniciativas!E$5:E$104<>"Completada"),11)),"—") -> — | D25: =IFERROR(INDEX(Iniciativas!E$5:E$104,aggregate(15,6,(ROW(Iniciativas!B$5:B$104)-ROW(Iniciativas!B$5)+1)*(Iniciativas!E$5:E$104<>"Completada"),11)),"—") -> — | E25: =IFERROR(INDEX(Iniciativas!F$5:F$104,aggregate(15,6,(ROW(Iniciativas!B$5:B$104)-ROW(Iniciativas!B$5)+1)*(Iniciativas!E$5:E$104<>"Completada"),11))/100,"—") -> — | F25: =IFERROR(INDEX(Iniciativas!G$5:G$104,aggregate(15,6,(ROW(Iniciativas!B$5:B$104)-ROW(Iniciativas!B$5)+1)*(Iniciativas!E$5:E$104<>"Completada"),11)),"—") -> — | G25: =IFERROR(INDEX(Iniciativas!J$5:J$104,aggregate(15,6,(ROW(Iniciativas!B$5:B$104)-ROW(Iniciativas!B$5)+1)*(Iniciativas!E$5:E$104<>"Completada"),11)),"—") -> —
B26: =IFERROR(INDEX(Iniciativas!B$5:B$104,aggregate(15,6,(ROW(Iniciativas!B$5:B$104)-ROW(Iniciativas!B$5)+1)*(Iniciativas!E$5:E$104<>"Completada"),12)),"—") -> — | C26: =IFERROR(INDEX(Iniciativas!C$5:C$104,aggregate(15,6,(ROW(Iniciativas!B$5:B$104)-ROW(Iniciativas!B$5)+1)*(Iniciativas!E$5:E$104<>"Completada"),12)),"—") -> — | D26: =IFERROR(INDEX(Iniciativas!E$5:E$104,aggregate(15,6,(ROW(Iniciativas!B$5:B$104)-ROW(Iniciativas!B$5)+1)*(Iniciativas!E$5:E$104<>"Completada"),12)),"—") -> — | E26: =IFERROR(INDEX(Iniciativas!F$5:F$104,aggregate(15,6,(ROW(Iniciativas!B$5:B$104)-ROW(Iniciativas!B$5)+1)*(Iniciativas!E$5:E$104<>"Completada"),12))/100,"—") -> — | F26: =IFERROR(INDEX(Iniciativas!G$5:G$104,aggregate(15,6,(ROW(Iniciativas!B$5:B$104)-ROW(Iniciativas!B$5)+1)*(Iniciativas!E$5:E$104<>"Completada"),12)),"—") -> — | G26: =IFERROR(INDEX(Iniciativas!J$5:J$104,aggregate(15,6,(ROW(Iniciativas!B$5:B$104)-ROW(Iniciativas!B$5)+1)*(Iniciativas!E$5:E$104<>"Completada"),12)),"—") -> —
B27: =IFERROR(INDEX(Iniciativas!B$5:B$104,aggregate(15,6,(ROW(Iniciativas!B$5:B$104)-ROW(Iniciativas!B$5)+1)*(Iniciativas!E$5:E$104<>"Completada"),13)),"—") -> — | C27: =IFERROR(INDEX(Iniciativas!C$5:C$104,aggregate(15,6,(ROW(Iniciativas!B$5:B$104)-ROW(Iniciativas!B$5)+1)*(Iniciativas!E$5:E$104<>"Completada"),13)),"—") -> — | D27: =IFERROR(INDEX(Iniciativas!E$5:E$104,aggregate(15,6,(ROW(Iniciativas!B$5:B$104)-ROW(Iniciativas!B$5)+1)*(Iniciativas!E$5:E$104<>"Completada"),13)),"—") -> — | E27: =IFERROR(INDEX(Iniciativas!F$5:F$104,aggregate(15,6,(ROW(Iniciativas!B$5:B$104)-ROW(Iniciativas!B$5)+1)*(Iniciativas!E$5:E$104<>"Completada"),13))/100,"—") -> — | F27: =IFERROR(INDEX(Iniciativas!G$5:G$104,aggregate(15,6,(ROW(Iniciativas!B$5:B$104)-ROW(Iniciativas!B$5)+1)*(Iniciativas!E$5:E$104<>"Completada"),13)),"—") -> — | G27: =IFERROR(INDEX(Iniciativas!J$5:J$104,aggregate(15,6,(ROW(Iniciativas!B$5:B$104)-ROW(Iniciativas!B$5)+1)*(Iniciativas!E$5:E$104<>"Completada"),13)),"—") -> —
B28: =IFERROR(INDEX(Iniciativas!B$5:B$104,aggregate(15,6,(ROW(Iniciativas!B$5:B$104)-ROW(Iniciativas!B$5)+1)*(Iniciativas!E$5:E$104<>"Completada"),14)),"—") -> — | C28: =IFERROR(INDEX(Iniciativas!C$5:C$104,aggregate(15,6,(ROW(Iniciativas!B$5:B$104)-ROW(Iniciativas!B$5)+1)*(Iniciativas!E$5:E$104<>"Completada"),14)),"—") -> — | D28: =IFERROR(INDEX(Iniciativas!E$5:E$104,aggregate(15,6,(ROW(Iniciativas!B$5:B$104)-ROW(Iniciativas!B$5)+1)*(Iniciativas!E$5:E$104<>"Completada"),14)),"—") -> — | E28: =IFERROR(INDEX(Iniciativas!F$5:F$104,aggregate(15,6,(ROW(Iniciativas!B$5:B$104)-ROW(Iniciativas!B$5)+1)*(Iniciativas!E$5:E$104<>"Completada"),14))/100,"—") -> — | F28: =IFERROR(INDEX(Iniciativas!G$5:G$104,aggregate(15,6,(ROW(Iniciativas!B$5:B$104)-ROW(Iniciativas!B$5)+1)*(Iniciativas!E$5:E$104<>"Completada"),14)),"—") -> — | G28: =IFERROR(INDEX(Iniciativas!J$5:J$104,aggregate(15,6,(ROW(Iniciativas!B$5:B$104)-ROW(Iniciativas!B$5)+1)*(Iniciativas!E$5:E$104<>"Completada"),14)),"—") -> —
B29: =IFERROR(INDEX(Iniciativas!B$5:B$104,aggregate(15,6,(ROW(Iniciativas!B$5:B$104)-ROW(Iniciativas!B$5)+1)*(Iniciativas!E$5:E$104<>"Completada"),15)),"—") -> — | C29: =IFERROR(INDEX(Iniciativas!C$5:C$104,aggregate(15,6,(ROW(Iniciativas!B$5:B$104)-ROW(Iniciativas!B$5)+1)*(Iniciativas!E$5:E$104<>"Completada"),15)),"—") -> — | D29: =IFERROR(INDEX(Iniciativas!E$5:E$104,aggregate(15,6,(ROW(Iniciativas!B$5:B$104)-ROW(Iniciativas!B$5)+1)*(Iniciativas!E$5:E$104<>"Completada"),15)),"—") -> — | E29: =IFERROR(INDEX(Iniciativas!F$5:F$104,aggregate(15,6,(ROW(Iniciativas!B$5:B$104)-ROW(Iniciativas!B$5)+1)*(Iniciativas!E$5:E$104<>"Completada"),15))/100,"—") -> — | F29: =IFERROR(INDEX(Iniciativas!G$5:G$104,aggregate(15,6,(ROW(Iniciativas!B$5:B$104)-ROW(Iniciativas!B$5)+1)*(Iniciativas!E$5:E$104<>"Completada"),15)),"—") -> — | G29: =IFERROR(INDEX(Iniciativas!J$5:J$104,aggregate(15,6,(ROW(Iniciativas!B$5:B$104)-ROW(Iniciativas!B$5)+1)*(Iniciativas!E$5:E$104<>"Completada"),15)),"—") -> —
B30: =IFERROR(INDEX(Iniciativas!B$5:B$104,aggregate(15,6,(ROW(Iniciativas!B$5:B$104)-ROW(Iniciativas!B$5)+1)*(Iniciativas!E$5:E$104<>"Completada"),16)),"—") -> — | C30: =IFERROR(INDEX(Iniciativas!C$5:C$104,aggregate(15,6,(ROW(Iniciativas!B$5:B$104)-ROW(Iniciativas!B$5)+1)*(Iniciativas!E$5:E$104<>"Completada"),16)),"—") -> — | D30: =IFERROR(INDEX(Iniciativas!E$5:E$104,aggregate(15,6,(ROW(Iniciativas!B$5:B$104)-ROW(Iniciativas!B$5)+1)*(Iniciativas!E$5:E$104<>"Completada"),16)),"—") -> — | E30: =IFERROR(INDEX(Iniciativas!F$5:F$104,aggregate(15,6,(ROW(Iniciativas!B$5:B$104)-ROW(Iniciativas!B$5)+1)*(Iniciativas!E$5:E$104<>"Completada"),16))/100,"—") -> — | F30: =IFERROR(INDEX(Iniciativas!G$5:G$104,aggregate(15,6,(ROW(Iniciativas!B$5:B$104)-ROW(Iniciativas!B$5)+1)*(Iniciativas!E$5:E$104<>"Completada"),16)),"—") -> — | G30: =IFERROR(INDEX(Iniciativas!J$5:J$104,aggregate(15,6,(ROW(Iniciativas!B$5:B$104)-ROW(Iniciativas!B$5)+1)*(Iniciativas!E$5:E$104<>"Completada"),16)),"—") -> —
B31: =IFERROR(INDEX(Iniciativas!B$5:B$104,aggregate(15,6,(ROW(Iniciativas!B$5:B$104)-ROW(Iniciativas!B$5)+1)*(Iniciativas!E$5:E$104<>"Completada"),17)),"—") -> — | C31: =IFERROR(INDEX(Iniciativas!C$5:C$104,aggregate(15,6,(ROW(Iniciativas!B$5:B$104)-ROW(Iniciativas!B$5)+1)*(Iniciativas!E$5:E$104<>"Completada"),17)),"—") -> — | D31: =IFERROR(INDEX(Iniciativas!E$5:E$104,aggregate(15,6,(ROW(Iniciativas!B$5:B$104)-ROW(Iniciativas!B$5)+1)*(Iniciativas!E$5:E$104<>"Completada"),17)),"—") -> — | E31: =IFERROR(INDEX(Iniciativas!F$5:F$104,aggregate(15,6,(ROW(Iniciativas!B$5:B$104)-ROW(Iniciativas!B$5)+1)*(Iniciativas!E$5:E$104<>"Completada"),17))/100,"—") -> — | F31: =IFERROR(INDEX(Iniciativas!G$5:G$104,aggregate(15,6,(ROW(Iniciativas!B$5:B$104)-ROW(Iniciativas!B$5)+1)*(Iniciativas!E$5:E$104<>"Completada"),17)),"—") -> — | G31: =IFERROR(INDEX(Iniciativas!J$5:J$104,aggregate(15,6,(ROW(Iniciativas!B$5:B$104)-ROW(Iniciativas!B$5)+1)*(Iniciativas!E$5:E$104<>"Completada"),17)),"—") -> —
B32: =IFERROR(INDEX(Iniciativas!B$5:B$104,aggregate(15,6,(ROW(Iniciativas!B$5:B$104)-ROW(Iniciativas!B$5)+1)*(Iniciativas!E$5:E$104<>"Completada"),18)),"—") -> — | C32: =IFERROR(INDEX(Iniciativas!C$5:C$104,aggregate(15,6,(ROW(Iniciativas!B$5:B$104)-ROW(Iniciativas!B$5)+1)*(Iniciativas!E$5:E$104<>"Completada"),18)),"—") -> — | D32: =IFERROR(INDEX(Iniciativas!E$5:E$104,aggregate(15,6,(ROW(Iniciativas!B$5:B$104)-ROW(Iniciativas!B$5)+1)*(Iniciativas!E$5:E$104<>"Completada"),18)),"—") -> — | E32: =IFERROR(INDEX(Iniciativas!F$5:F$104,aggregate(15,6,(ROW(Iniciativas!B$5:B$104)-ROW(Iniciativas!B$5)+1)*(Iniciativas!E$5:E$104<>"Completada"),18))/100,"—") -> — | F32: =IFERROR(INDEX(Iniciativas!G$5:G$104,aggregate(15,6,(ROW(Iniciativas!B$5:B$104)-ROW(Iniciativas!B$5)+1)*(Iniciativas!E$5:E$104<>"Completada"),18)),"—") -> — | G32: =IFERROR(INDEX(Iniciativas!J$5:J$104,aggregate(15,6,(ROW(Iniciativas!B$5:B$104)-ROW(Iniciativas!B$5)+1)*(Iniciativas!E$5:E$104<>"Completada"),18)),"—") -> —
B33: =IFERROR(INDEX(Iniciativas!B$5:B$104,aggregate(15,6,(ROW(Iniciativas!B$5:B$104)-ROW(Iniciativas!B$5)+1)*(Iniciativas!E$5:E$104<>"Completada"),19)),"—") -> — | C33: =IFERROR(INDEX(Iniciativas!C$5:C$104,aggregate(15,6,(ROW(Iniciativas!B$5:B$104)-ROW(Iniciativas!B$5)+1)*(Iniciativas!E$5:E$104<>"Completada"),19)),"—") -> — | D33: =IFERROR(INDEX(Iniciativas!E$5:E$104,aggregate(15,6,(ROW(Iniciativas!B$5:B$104)-ROW(Iniciativas!B$5)+1)*(Iniciativas!E$5:E$104<>"Completada"),19)),"—") -> — | E33: =IFERROR(INDEX(Iniciativas!F$5:F$104,aggregate(15,6,(ROW(Iniciativas!B$5:B$104)-ROW(Iniciativas!B$5)+1)*(Iniciativas!E$5:E$104<>"Completada"),19))/100,"—") -> — | F33: =IFERROR(INDEX(Iniciativas!G$5:G$104,aggregate(15,6,(ROW(Iniciativas!B$5:B$104)-ROW(Iniciativas!B$5)+1)*(Iniciativas!E$5:E$104<>"Completada"),19)),"—") -> — | G33: =IFERROR(INDEX(Iniciativas!J$5:J$104,aggregate(15,6,(ROW(Iniciativas!B$5:B$104)-ROW(Iniciativas!B$5)+1)*(Iniciativas!E$5:E$104<>"Completada"),19)),"—") -> —
B34: =IFERROR(INDEX(Iniciativas!B$5:B$104,aggregate(15,6,(ROW(Iniciativas!B$5:B$104)-ROW(Iniciativas!B$5)+1)*(Iniciativas!E$5:E$104<>"Completada"),20)),"—") -> — | C34: =IFERROR(INDEX(Iniciativas!C$5:C$104,aggregate(15,6,(ROW(Iniciativas!B$5:B$104)-ROW(Iniciativas!B$5)+1)*(Iniciativas!E$5:E$104<>"Completada"),20)),"—") -> — | D34: =IFERROR(INDEX(Iniciativas!E$5:E$104,aggregate(15,6,(ROW(Iniciativas!B$5:B$104)-ROW(Iniciativas!B$5)+1)*(Iniciativas!E$5:E$104<>"Completada"),20)),"—") -> — | E34: =IFERROR(INDEX(Iniciativas!F$5:F$104,aggregate(15,6,(ROW(Iniciativas!B$5:B$104)-ROW(Iniciativas!B$5)+1)*(Iniciativas!E$5:E$104<>"Completada"),20))/100,"—") -> — | F34: =IFERROR(INDEX(Iniciativas!G$5:G$104,aggregate(15,6,(ROW(Iniciativas!B$5:B$104)-ROW(Iniciativas!B$5)+1)*(Iniciativas!E$5:E$104<>"Completada"),20)),"—") -> — | G34: =IFERROR(INDEX(Iniciativas!J$5:J$104,aggregate(15,6,(ROW(Iniciativas!B$5:B$104)-ROW(Iniciativas!B$5)+1)*(Iniciativas!E$5:E$104<>"Completada"),20)),"—") -> —
B35: =IFERROR(INDEX(Iniciativas!B$5:B$104,aggregate(15,6,(ROW(Iniciativas!B$5:B$104)-ROW(Iniciativas!B$5)+1)*(Iniciativas!E$5:E$104<>"Completada"),21)),"—") -> — | C35: =IFERROR(INDEX(Iniciativas!C$5:C$104,aggregate(15,6,(ROW(Iniciativas!B$5:B$104)-ROW(Iniciativas!B$5)+1)*(Iniciativas!E$5:E$104<>"Completada"),21)),"—") -> — | D35: =IFERROR(INDEX(Iniciativas!E$5:E$104,aggregate(15,6,(ROW(Iniciativas!B$5:B$104)-ROW(Iniciativas!B$5)+1)*(Iniciativas!E$5:E$104<>"Completada"),21)),"—") -> — | E35: =IFERROR(INDEX(Iniciativas!F$5:F$104,aggregate(15,6,(ROW(Iniciativas!B$5:B$104)-ROW(Iniciativas!B$5)+1)*(Iniciativas!E$5:E$104<>"Completada"),21))/100,"—") -> — | F35: =IFERROR(INDEX(Iniciativas!G$5:G$104,aggregate(15,6,(ROW(Iniciativas!B$5:B$104)-ROW(Iniciativas!B$5)+1)*(Iniciativas!E$5:E$104<>"Completada"),21)),"—") -> — | G35: =IFERROR(INDEX(Iniciativas!J$5:J$104,aggregate(15,6,(ROW(Iniciativas!B$5:B$104)-ROW(Iniciativas!B$5)+1)*(Iniciativas!E$5:E$104<>"Completada"),21)),"—") -> —
B36: =IFERROR(INDEX(Iniciativas!B$5:B$104,aggregate(15,6,(ROW(Iniciativas!B$5:B$104)-ROW(Iniciativas!B$5)+1)*(Iniciativas!E$5:E$104<>"Completada"),22)),"—") -> — | C36: =IFERROR(INDEX(Iniciativas!C$5:C$104,aggregate(15,6,(ROW(Iniciativas!B$5:B$104)-ROW(Iniciativas!B$5)+1)*(Iniciativas!E$5:E$104<>"Completada"),22)),"—") -> — | D36: =IFERROR(INDEX(Iniciativas!E$5:E$104,aggregate(15,6,(ROW(Iniciativas!B$5:B$104)-ROW(Iniciativas!B$5)+1)*(Iniciativas!E$5:E$104<>"Completada"),22)),"—") -> — | E36: =IFERROR(INDEX(Iniciativas!F$5:F$104,aggregate(15,6,(ROW(Iniciativas!B$5:B$104)-ROW(Iniciativas!B$5)+1)*(Iniciativas!E$5:E$104<>"Completada"),22))/100,"—") -> — | F36: =IFERROR(INDEX(Iniciativas!G$5:G$104,aggregate(15,6,(ROW(Iniciativas!B$5:B$104)-ROW(Iniciativas!B$5)+1)*(Iniciativas!E$5:E$104<>"Completada"),22)),"—") -> — | G36: =IFERROR(INDEX(Iniciativas!J$5:J$104,aggregate(15,6,(ROW(Iniciativas!B$5:B$104)-ROW(Iniciativas!B$5)+1)*(Iniciativas!E$5:E$104<>"Completada"),22)),"—") -> —
B37: =IFERROR(INDEX(Iniciativas!B$5:B$104,aggregate(15,6,(ROW(Iniciativas!B$5:B$104)-ROW(Iniciativas!B$5)+1)*(Iniciativas!E$5:E$104<>"Completada"),23)),"—") -> — | C37: =IFERROR(INDEX(Iniciativas!C$5:C$104,aggregate(15,6,(ROW(Iniciativas!B$5:B$104)-ROW(Iniciativas!B$5)+1)*(Iniciativas!E$5:E$104<>"Completada"),23)),"—") -> — | D37: =IFERROR(INDEX(Iniciativas!E$5:E$104,aggregate(15,6,(ROW(Iniciativas!B$5:B$104)-ROW(Iniciativas!B$5)+1)*(Iniciativas!E$5:E$104<>"Completada"),23)),"—") -> — | E37: =IFERROR(INDEX(Iniciativas!F$5:F$104,aggregate(15,6,(ROW(Iniciativas!B$5:B$104)-ROW(Iniciativas!B$5)+1)*(Iniciativas!E$5:E$104<>"Completada"),23))/100,"—") -> — | F37: =IFERROR(INDEX(Iniciativas!G$5:G$104,aggregate(15,6,(ROW(Iniciativas!B$5:B$104)-ROW(Iniciativas!B$5)+1)*(Iniciativas!E$5:E$104<>"Completada"),23)),"—") -> — | G37: =IFERROR(INDEX(Iniciativas!J$5:J$104,aggregate(15,6,(ROW(Iniciativas!B$5:B$104)-ROW(Iniciativas!B$5)+1)*(Iniciativas!E$5:E$104<>"Completada"),23)),"—") -> —
B38: =IFERROR(INDEX(Iniciativas!B$5:B$104,aggregate(15,6,(ROW(Iniciativas!B$5:B$104)-ROW(Iniciativas!B$5)+1)*(Iniciativas!E$5:E$104<>"Completada"),24)),"—") -> — | C38: =IFERROR(INDEX(Iniciativas!C$5:C$104,aggregate(15,6,(ROW(Iniciativas!B$5:B$104)-ROW(Iniciativas!B$5)+1)*(Iniciativas!E$5:E$104<>"Completada"),24)),"—") -> — | D38: =IFERROR(INDEX(Iniciativas!E$5:E$104,aggregate(15,6,(ROW(Iniciativas!B$5:B$104)-ROW(Iniciativas!B$5)+1)*(Iniciativas!E$5:E$104<>"Completada"),24)),"—") -> — | E38: =IFERROR(INDEX(Iniciativas!F$5:F$104,aggregate(15,6,(ROW(Iniciativas!B$5:B$104)-ROW(Iniciativas!B$5)+1)*(Iniciativas!E$5:E$104<>"Completada"),24))/100,"—") -> — | F38: =IFERROR(INDEX(Iniciativas!G$5:G$104,aggregate(15,6,(ROW(Iniciativas!B$5:B$104)-ROW(Iniciativas!B$5)+1)*(Iniciativas!E$5:E$104<>"Completada"),24)),"—") -> — | G38: =IFERROR(INDEX(Iniciativas!J$5:J$104,aggregate(15,6,(ROW(Iniciativas!B$5:B$104)-ROW(Iniciativas!B$5)+1)*(Iniciativas!E$5:E$104<>"Completada"),24)),"—") -> —
B39: =IFERROR(INDEX(Iniciativas!B$5:B$104,aggregate(15,6,(ROW(Iniciativas!B$5:B$104)-ROW(Iniciativas!B$5)+1)*(Iniciativas!E$5:E$104<>"Completada"),25)),"—") -> — | C39: =IFERROR(INDEX(Iniciativas!C$5:C$104,aggregate(15,6,(ROW(Iniciativas!B$5:B$104)-ROW(Iniciativas!B$5)+1)*(Iniciativas!E$5:E$104<>"Completada"),25)),"—") -> — | D39: =IFERROR(INDEX(Iniciativas!E$5:E$104,aggregate(15,6,(ROW(Iniciativas!B$5:B$104)-ROW(Iniciativas!B$5)+1)*(Iniciativas!E$5:E$104<>"Completada"),25)),"—") -> — | E39: =IFERROR(INDEX(Iniciativas!F$5:F$104,aggregate(15,6,(ROW(Iniciativas!B$5:B$104)-ROW(Iniciativas!B$5)+1)*(Iniciativas!E$5:E$104<>"Completada"),25))/100,"—") -> — | F39: =IFERROR(INDEX(Iniciativas!G$5:G$104,aggregate(15,6,(ROW(Iniciativas!B$5:B$104)-ROW(Iniciativas!B$5)+1)*(Iniciativas!E$5:E$104<>"Completada"),25)),"—") -> — | G39: =IFERROR(INDEX(Iniciativas!J$5:J$104,aggregate(15,6,(ROW(Iniciativas!B$5:B$104)-ROW(Iniciativas!B$5)+1)*(Iniciativas!E$5:E$104<>"Completada"),25)),"—") -> —
B40: =IFERROR(INDEX(Iniciativas!B$5:B$104,aggregate(15,6,(ROW(Iniciativas!B$5:B$104)-ROW(Iniciativas!B$5)+1)*(Iniciativas!E$5:E$104<>"Completada"),26)),"—") -> — | C40: =IFERROR(INDEX(Iniciativas!C$5:C$104,aggregate(15,6,(ROW(Iniciativas!B$5:B$104)-ROW(Iniciativas!B$5)+1)*(Iniciativas!E$5:E$104<>"Completada"),26)),"—") -> — | D40: =IFERROR(INDEX(Iniciativas!E$5:E$104,aggregate(15,6,(ROW(Iniciativas!B$5:B$104)-ROW(Iniciativas!B$5)+1)*(Iniciativas!E$5:E$104<>"Completada"),26)),"—") -> — | E40: =IFERROR(INDEX(Iniciativas!F$5:F$104,aggregate(15,6,(ROW(Iniciativas!B$5:B$104)-ROW(Iniciativas!B$5)+1)*(Iniciativas!E$5:E$104<>"Completada"),26))/100,"—") -> — | F40: =IFERROR(INDEX(Iniciativas!G$5:G$104,aggregate(15,6,(ROW(Iniciativas!B$5:B$104)-ROW(Iniciativas!B$5)+1)*(Iniciativas!E$5:E$104<>"Completada"),26)),"—") -> — | G40: =IFERROR(INDEX(Iniciativas!J$5:J$104,aggregate(15,6,(ROW(Iniciativas!B$5:B$104)-ROW(Iniciativas!B$5)+1)*(Iniciativas!E$5:E$104<>"Completada"),26)),"—") -> —
B41: =IFERROR(INDEX(Iniciativas!B$5:B$104,aggregate(15,6,(ROW(Iniciativas!B$5:B$104)-ROW(Iniciativas!B$5)+1)*(Iniciativas!E$5:E$104<>"Completada"),27)),"—") -> — | C41: =IFERROR(INDEX(Iniciativas!C$5:C$104,aggregate(15,6,(ROW(Iniciativas!B$5:B$104)-ROW(Iniciativas!B$5)+1)*(Iniciativas!E$5:E$104<>"Completada"),27)),"—") -> — | D41: =IFERROR(INDEX(Iniciativas!E$5:E$104,aggregate(15,6,(ROW(Iniciativas!B$5:B$104)-ROW(Iniciativas!B$5)+1)*(Iniciativas!E$5:E$104<>"Completada"),27)),"—") -> — | E41: =IFERROR(INDEX(Iniciativas!F$5:F$104,aggregate(15,6,(ROW(Iniciativas!B$5:B$104)-ROW(Iniciativas!B$5)+1)*(Iniciativas!E$5:E$104<>"Completada"),27))/100,"—") -> — | F41: =IFERROR(INDEX(Iniciativas!G$5:G$104,aggregate(15,6,(ROW(Iniciativas!B$5:B$104)-ROW(Iniciativas!B$5)+1)*(Iniciativas!E$5:E$104<>"Completada"),27)),"—") -> — | G41: =IFERROR(INDEX(Iniciativas!J$5:J$104,aggregate(15,6,(ROW(Iniciativas!B$5:B$104)-ROW(Iniciativas!B$5)+1)*(Iniciativas!E$5:E$104<>"Completada"),27)),"—") -> —
B42: =IFERROR(INDEX(Iniciativas!B$5:B$104,aggregate(15,6,(ROW(Iniciativas!B$5:B$104)-ROW(Iniciativas!B$5)+1)*(Iniciativas!E$5:E$104<>"Completada"),28)),"—") -> — | C42: =IFERROR(INDEX(Iniciativas!C$5:C$104,aggregate(15,6,(ROW(Iniciativas!B$5:B$104)-ROW(Iniciativas!B$5)+1)*(Iniciativas!E$5:E$104<>"Completada"),28)),"—") -> — | D42: =IFERROR(INDEX(Iniciativas!E$5:E$104,aggregate(15,6,(ROW(Iniciativas!B$5:B$104)-ROW(Iniciativas!B$5)+1)*(Iniciativas!E$5:E$104<>"Completada"),28)),"—") -> — | E42: =IFERROR(INDEX(Iniciativas!F$5:F$104,aggregate(15,6,(ROW(Iniciativas!B$5:B$104)-ROW(Iniciativas!B$5)+1)*(Iniciativas!E$5:E$104<>"Completada"),28))/100,"—") -> — | F42: =IFERROR(INDEX(Iniciativas!G$5:G$104,aggregate(15,6,(ROW(Iniciativas!B$5:B$104)-ROW(Iniciativas!B$5)+1)*(Iniciativas!E$5:E$104<>"Completada"),28)),"—") -> — | G42: =IFERROR(INDEX(Iniciativas!J$5:J$104,aggregate(15,6,(ROW(Iniciativas!B$5:B$104)-ROW(Iniciativas!B$5)+1)*(Iniciativas!E$5:E$104<>"Completada"),28)),"—") -> —
B43: =IFERROR(INDEX(Iniciativas!B$5:B$104,aggregate(15,6,(ROW(Iniciativas!B$5:B$104)-ROW(Iniciativas!B$5)+1)*(Iniciativas!E$5:E$104<>"Completada"),29)),"—") -> — | C43: =IFERROR(INDEX(Iniciativas!C$5:C$104,aggregate(15,6,(ROW(Iniciativas!B$5:B$104)-ROW(Iniciativas!B$5)+1)*(Iniciativas!E$5:E$104<>"Completada"),29)),"—") -> — | D43: =IFERROR(INDEX(Iniciativas!E$5:E$104,aggregate(15,6,(ROW(Iniciativas!B$5:B$104)-ROW(Iniciativas!B$5)+1)*(Iniciativas!E$5:E$104<>"Completada"),29)),"—") -> — | E43: =IFERROR(INDEX(Iniciativas!F$5:F$104,aggregate(15,6,(ROW(Iniciativas!B$5:B$104)-ROW(Iniciativas!B$5)+1)*(Iniciativas!E$5:E$104<>"Completada"),29))/100,"—") -> — | F43: =IFERROR(INDEX(Iniciativas!G$5:G$104,aggregate(15,6,(ROW(Iniciativas!B$5:B$104)-ROW(Iniciativas!B$5)+1)*(Iniciativas!E$5:E$104<>"Completada"),29)),"—") -> — | G43: =IFERROR(INDEX(Iniciativas!J$5:J$104,aggregate(15,6,(ROW(Iniciativas!B$5:B$104)-ROW(Iniciativas!B$5)+1)*(Iniciativas!E$5:E$104<>"Completada"),29)),"—") -> —
...
